2024-03-14 07:17:31,144 INFO    StreamThr :1028 [internal.py:wandb_internal():86] W&B internal server running at pid: 1028, started at: 2024-03-14 07:17:31.144431
2024-03-14 07:17:31,146 DEBUG   HandlerThread:1028 [handler.py:handle_request():146] handle_request: status
2024-03-14 07:17:31,148 INFO    WriterThread:1028 [datastore.py:open_for_write():87] open: C:\Users\Ludwig\python code\fps_prj\wandb\run-20240314_071731-jc0k3psg\run-jc0k3psg.wandb
2024-03-14 07:17:31,149 DEBUG   SenderThread:1028 [sender.py:send():382] send: header
2024-03-14 07:17:31,149 DEBUG   SenderThread:1028 [sender.py:send():382] send: run
2024-03-14 07:17:36,177 DEBUG   HandlerThread:1028 [handler.py:handle_request():146] handle_request: keepalive
2024-03-14 07:17:41,193 DEBUG   HandlerThread:1028 [handler.py:handle_request():146] handle_request: keepalive
2024-03-14 07:17:46,215 DEBUG   HandlerThread:1028 [handler.py:handle_request():146] handle_request: keepalive
2024-03-14 07:17:51,245 DEBUG   HandlerThread:1028 [handler.py:handle_request():146] handle_request: keepalive
2024-03-14 07:17:56,265 DEBUG   HandlerThread:1028 [handler.py:handle_request():146] handle_request: keepalive
2024-03-14 07:18:01,283 DEBUG   HandlerThread:1028 [handler.py:handle_request():146] handle_request: keepalive
2024-03-14 07:18:06,301 DEBUG   HandlerThread:1028 [handler.py:handle_request():146] handle_request: keepalive
2024-03-14 07:18:11,322 DEBUG   HandlerThread:1028 [handler.py:handle_request():146] handle_request: keepalive
2024-03-14 07:18:16,351 DEBUG   HandlerThread:1028 [handler.py:handle_request():146] handle_request: keepalive
2024-03-14 07:18:21,370 DEBUG   HandlerThread:1028 [handler.py:handle_request():146] handle_request: keepalive
2024-03-14 07:18:26,391 DEBUG   HandlerThread:1028 [handler.py:handle_request():146] handle_request: keepalive
2024-03-14 07:18:31,410 DEBUG   HandlerThread:1028 [handler.py:handle_request():146] handle_request: keepalive
2024-03-14 07:18:34,693 INFO    SenderThread:1028 [retry.py:__call__():172] Retry attempt failed:
Traceback (most recent call last):
  File "C:\Users\Ludwig\anaconda3\envs\mlsci\Lib\site-packages\urllib3\connection.py", line 198, in _new_conn
    sock = connection.create_connection(
           ^^^^^^^^^^^^^^^^^^^^^^^^^^^^^
  File "C:\Users\Ludwig\anaconda3\envs\mlsci\Lib\site-packages\urllib3\util\connection.py", line 85, in create_connection
    raise err
  File "C:\Users\Ludwig\anaconda3\envs\mlsci\Lib\site-packages\urllib3\util\connection.py", line 73, in create_connection
    sock.connect(sa)
TimeoutError: timed out

The above exception was the direct cause of the following exception:

Traceback (most recent call last):
  File "C:\Users\Ludwig\anaconda3\envs\mlsci\Lib\site-packages\urllib3\connectionpool.py", line 793, in urlopen
    response = self._make_request(
               ^^^^^^^^^^^^^^^^^^^
  File "C:\Users\Ludwig\anaconda3\envs\mlsci\Lib\site-packages\urllib3\connectionpool.py", line 491, in _make_request
    raise new_e
  File "C:\Users\Ludwig\anaconda3\envs\mlsci\Lib\site-packages\urllib3\connectionpool.py", line 467, in _make_request
    self._validate_conn(conn)
  File "C:\Users\Ludwig\anaconda3\envs\mlsci\Lib\site-packages\urllib3\connectionpool.py", line 1099, in _validate_conn
    conn.connect()
  File "C:\Users\Ludwig\anaconda3\envs\mlsci\Lib\site-packages\urllib3\connection.py", line 616, in connect
    self.sock = sock = self._new_conn()
                       ^^^^^^^^^^^^^^^^
  File "C:\Users\Ludwig\anaconda3\envs\mlsci\Lib\site-packages\urllib3\connection.py", line 207, in _new_conn
    raise ConnectTimeoutError(
urllib3.exceptions.ConnectTimeoutError: (<urllib3.connection.HTTPSConnection object at 0x00000205D73B3310>, 'Connection to api.wandb.ai timed out. (connect timeout=20)')

The above exception was the direct cause of the following exception:

Traceback (most recent call last):
  File "C:\Users\Ludwig\anaconda3\envs\mlsci\Lib\site-packages\requests\adapters.py", line 486, in send
    resp = conn.urlopen(
           ^^^^^^^^^^^^^
  File "C:\Users\Ludwig\anaconda3\envs\mlsci\Lib\site-packages\urllib3\connectionpool.py", line 847, in urlopen
    retries = retries.increment(
              ^^^^^^^^^^^^^^^^^^
  File "C:\Users\Ludwig\anaconda3\envs\mlsci\Lib\site-packages\urllib3\util\retry.py", line 515, in increment
    raise MaxRetryError(_pool, url, reason) from reason  # type: ignore[arg-type]
    ^^^^^^^^^^^^^^^^^^^^^^^^^^^^^^^^^^^^^^^^^^^^^^^^^^^
urllib3.exceptions.MaxRetryError: HTTPSConnectionPool(host='api.wandb.ai', port=443): Max retries exceeded with url: /graphql (Caused by ConnectTimeoutError(<urllib3.connection.HTTPSConnection object at 0x00000205D73B3310>, 'Connection to api.wandb.ai timed out. (connect timeout=20)'))

During handling of the above exception, another exception occurred:

Traceback (most recent call last):
  File "C:\Users\Ludwig\anaconda3\envs\mlsci\Lib\site-packages\wandb\sdk\lib\retry.py", line 131, in __call__
    result = self._call_fn(*args, **kwargs)
             ^^^^^^^^^^^^^^^^^^^^^^^^^^^^^^
  File "C:\Users\Ludwig\anaconda3\envs\mlsci\Lib\site-packages\wandb\sdk\internal\internal_api.py", line 369, in execute
    return self.client.execute(*args, **kwargs)  # type: ignore
           ^^^^^^^^^^^^^^^^^^^^^^^^^^^^^^^^^^^^
  File "C:\Users\Ludwig\anaconda3\envs\mlsci\Lib\site-packages\wandb\vendor\gql-0.2.0\wandb_gql\client.py", line 52, in execute
    result = self._get_result(document, *args, **kwargs)
             ^^^^^^^^^^^^^^^^^^^^^^^^^^^^^^^^^^^^^^^^^^^
  File "C:\Users\Ludwig\anaconda3\envs\mlsci\Lib\site-packages\wandb\vendor\gql-0.2.0\wandb_gql\client.py", line 60, in _get_result
    return self.transport.execute(document, *args, **kwargs)
           ^^^^^^^^^^^^^^^^^^^^^^^^^^^^^^^^^^^^^^^^^^^^^^^^^
  File "C:\Users\Ludwig\anaconda3\envs\mlsci\Lib\site-packages\wandb\sdk\lib\gql_request.py", line 58, in execute
    request = self.session.post(self.url, **post_args)
              ^^^^^^^^^^^^^^^^^^^^^^^^^^^^^^^^^^^^^^^^
  File "C:\Users\Ludwig\anaconda3\envs\mlsci\Lib\site-packages\requests\sessions.py", line 637, in post
    return self.request("POST", url, data=data, json=json, **kwargs)
           ^^^^^^^^^^^^^^^^^^^^^^^^^^^^^^^^^^^^^^^^^^^^^^^^^^^^^^^^^
  File "C:\Users\Ludwig\anaconda3\envs\mlsci\Lib\site-packages\requests\sessions.py", line 589, in request
    resp = self.send(prep, **send_kwargs)
           ^^^^^^^^^^^^^^^^^^^^^^^^^^^^^^
  File "C:\Users\Ludwig\anaconda3\envs\mlsci\Lib\site-packages\requests\sessions.py", line 703, in send
    r = adapter.send(request, **kwargs)
        ^^^^^^^^^^^^^^^^^^^^^^^^^^^^^^^
  File "C:\Users\Ludwig\anaconda3\envs\mlsci\Lib\site-packages\requests\adapters.py", line 507, in send
    raise ConnectTimeout(e, request=request)
requests.exceptions.ConnectTimeout: HTTPSConnectionPool(host='api.wandb.ai', port=443): Max retries exceeded with url: /graphql (Caused by ConnectTimeoutError(<urllib3.connection.HTTPSConnection object at 0x00000205D73B3310>, 'Connection to api.wandb.ai timed out. (connect timeout=20)'))
2024-03-14 07:18:36,425 DEBUG   HandlerThread:1028 [handler.py:handle_request():146] handle_request: keepalive
2024-03-14 07:18:41,445 DEBUG   HandlerThread:1028 [handler.py:handle_request():146] handle_request: keepalive
2024-03-14 07:18:46,472 DEBUG   HandlerThread:1028 [handler.py:handle_request():146] handle_request: keepalive
2024-03-14 07:18:51,493 DEBUG   HandlerThread:1028 [handler.py:handle_request():146] handle_request: keepalive
2024-03-14 07:18:56,510 DEBUG   HandlerThread:1028 [handler.py:handle_request():146] handle_request: keepalive
2024-03-14 07:19:01,527 DEBUG   HandlerThread:1028 [handler.py:handle_request():146] handle_request: cancel
2024-03-14 07:19:01,528 DEBUG   HandlerThread:1028 [handler.py:handle_request():146] handle_request: cancel
2024-03-14 07:19:01,529 DEBUG   SenderThread:1028 [sender.py:send():391] Record cancelled: run
2024-03-14 07:19:01,530 DEBUG   HandlerThread:1028 [handler.py:handle_request():146] handle_request: status_report
2024-03-14 07:19:03,564 DEBUG   HandlerThread:1028 [handler.py:handle_request():146] handle_request: shutdown
2024-03-14 07:19:03,564 INFO    HandlerThread:1028 [handler.py:finish():869] shutting down handler
2024-03-14 07:19:04,540 INFO    SenderThread:1028 [sender.py:finish():1572] shutting down sender
2024-03-14 07:19:04,540 INFO    WriterThread:1028 [datastore.py:close():296] close: C:\Users\Ludwig\python code\fps_prj\wandb\run-20240314_071731-jc0k3psg\run-jc0k3psg.wandb
